ERROR:root:create_category_excel 실행 중 오류 발생: 'date'
Traceback (most recent call last):
  File "/Users/jay/Documents/GitHub/DNMD/event_planner/main.py", line 741, in wrapper
    return func(*args, **kwargs)
           ^^^^^^^^^^^^^^^^^^^^^
  File "/Users/jay/Documents/GitHub/DNMD/event_planner/main.py", line 1019, in create_category_excel
    ws['A' + str(row)] = f"납품일: {delivery['date']}"
                                    ~~~~~~~~^^^^^^^^
KeyError: 'date'
ERROR:root:create_category_excel 실행 중 오류 발생: 'date'
Traceback (most recent call last):
  File "/Users/jay/Documents/GitHub/DNMD/event_planner/main.py", line 741, in wrapper
    return func(*args, **kwargs)
           ^^^^^^^^^^^^^^^^^^^^^
  File "/Users/jay/Documents/GitHub/DNMD/event_planner/main.py", line 1019, in create_category_excel
    ws['A' + str(row)] = f"납품일: {delivery['date']}"
                                    ~~~~~~~~^^^^^^^^
KeyError: 'date'
ERROR:root:create_category_excel 실행 중 오류 발생: 'date'
Traceback (most recent call last):
  File "/Users/jay/Documents/GitHub/DNMD/event_planner/main.py", line 741, in wrapper
    return func(*args, **kwargs)
           ^^^^^^^^^^^^^^^^^^^^^
  File "/Users/jay/Documents/GitHub/DNMD/event_planner/main.py", line 1019, in create_category_excel
    ws['A' + str(row)] = f"납품일: {delivery['date']}"
                                    ~~~~~~~~^^^^^^^^
KeyError: 'date'
